<?xml version="1.0" encoding="utf-8"?>
<robot name="ur10">
    <link name="base_link">
        <collision>
            <origin xyz="0 0 0.02" rpy="0 0 0"/>
            <geometry>
                <cylinder radius="0.075" length="0.03"/>
            </geometry>
        </collision>
        <visual>
            <origin xyz="0 0 0" rpy="0 0 0"/>
            <geometry>
                <mesh filename="ur10/meshes/ur10_base.obj" scale="1 1 1"/>
            </geometry>
        </visual>
        <inertial>
            <mass value="200.0"/>
        </inertial>
    </link>
    <link name="shoulder_link">
        <visual>
            <origin xyz="0 0 -.1273" rpy="0 0 0"/>
            <geometry>
                <mesh filename="ur10/meshes/ur10_shoulder.obj" scale="1 1 1"/>
            </geometry>
        </visual>
        <collision>
            <origin xyz="0 0.0 0.0027000046)" rpy="0 0 0"/>
            <geometry>
                <cylinder radius="0.075" length="0.17"/>
            </geometry>
        </collision>
        <collision>
            <origin xyz="0 .0425  0.007000065" rpy="1.57079632679 0 0"/>
            <geometry>
                <cylinder radius="0.075" length="0.085"/>
            </geometry>
        </collision>
        <inertial>
            <mass value="7.1"/>
        </inertial>
    </link>
    <link name="upper_arm_link">
        <visual>
            <origin xyz="-0.0007000065 -0.044941006 0" rpy="0 -1.57079632679 0"/>
            <geometry>
                <mesh filename="ur10/meshes/ur10_upper_arm.obj" scale="1 1 1"/>
            </geometry>
        </visual>
        <collision>
            <origin xyz="-0.0007000065 -0.044941006 0" rpy="1.57079632679 0 0"/>
            <geometry>
                <cylinder radius="0.075" length="0.175"/>
            </geometry>
        </collision>
        <collision>
            <origin xyz="-0.0007000065 -0.044941006 0.306" rpy="0 0 0"/>
            <geometry>
                <cylinder radius="0.06" length="0.612"/>
            </geometry>
        </collision>
        <collision>
            <origin xyz="-0.0007000065 -0.044941006 0.612" rpy="1.57079632679 0 0"/>
            <geometry>
                <cylinder radius="0.06" length="0.136"/>
            </geometry>
        </collision>
        <inertial>
            <mass value="12.7"/>
        </inertial>
    </link>
    <link name="forearm_link">
        <visual>
            <origin xyz="-0.0007000351 -0.0010410404 0" rpy="0 -1.57079632679 0"/>
            <geometry>
                <mesh filename="ur10/meshes/ur10_forearm.obj" scale="1 1 1"/>
            </geometry>
        </visual>
        <collision>
            <origin xyz="-0.0007000351 -0.0041510403 0" rpy="1.57079632679 0 0"/>
            <geometry>
                <cylinder radius="0.06" length="0.126"/>
            </geometry>
        </collision>
        <collision>
            <origin xyz="-0.0007000351 -0.0010410404 0.286" rpy="0 0 0"/>
            <geometry>
                <cylinder radius="0.047" length="0.572"/>
            </geometry>
        </collision>
        <collision>
            <origin xyz="-0.0007000547 0.0017589596 0.572" rpy="1.57079632679 0 0"/>
            <geometry>
                <cylinder radius="0.047" length="0.118"/>
            </geometry>
        </collision>
        <inertial>
            <mass value="4.27"/>
        </inertial>
    </link>
    <link name="wrist_1_link">
        <visual>
            <origin xyz="0.0002999115 0.11495896 -0.0007000637" rpy="-3.14159265359 0 -3.14159265359"/>
            <geometry>
                <mesh filename="ur10/meshes/ur10_wrist_1.obj" scale="1 1 1"/>
            </geometry>
        </visual>
        <collision>
            <origin xyz="0.0002999115 0.08745896 -0.0007000637" rpy="1.57079632679 0 3.14159265359"/>
            <geometry>
                <cylinder radius="0.047" length="0.055"/>
            </geometry>
        </collision>
        <collision>
            <origin xyz="0.0002999115 0.11495896 0.0020999363" rpy="-3.14159265359 0 -3.14159265359"/>
            <geometry>
                <cylinder radius="0.047" length="0.118"/>
            </geometry>
        </collision>
        <inertial>
            <mass value="1.0"/>
        </inertial>
    </link>
    <link name="wrist_2_link">
        <visual>
            <origin xyz="0.0002999115 0.000058994293 0.11529993" rpy="-3.14159265359 0 -3.14159265359"/>
            <geometry>
                <mesh filename="ur10/meshes/ur10_wrist_2.obj" scale="1 1 1"/>
            </geometry>
        </visual>
        <collision>
            <origin xyz="0.0002999115 0.000058994293 0.08829992" rpy="-3.14159265359 0 -3.14159265359"/>
            <geometry>
                <cylinder radius="0.047" length="0.054"/>
            </geometry>
        </collision>
        <collision>
            <origin xyz="0.0002999115 0.0028589943 0.11529993" rpy="1.57079632679 0 3.14159265359"/>
            <geometry>
                <cylinder radius="0.047" length="0.118"/>
            </geometry>
        </collision>
        <inertial>
            <mass value="1.0"/>
        </inertial>
    </link>
    <link name="wrist_3_link">
        <visual>
            <origin xyz="0.0002999115 0.09205898 -0.00040007472" rpy="-3.14159265359 0 -3.14159265359"/>
            <geometry>
                <mesh filename="ur10/meshes/ur10_wrist_3.obj" scale="1 1 1"/>
            </geometry>
        </visual>
        <collision>
            <origin xyz="0.0002999115 0.077058983 -0.00040007472" rpy="1.57079632679 0 -3.14159265359"/>
            <geometry>
                <cylinder radius="0.047" length="0.03"/>
            </geometry>
        </collision>
        <inertial>
            <mass value="0.365"/>
        </inertial>
    </link>
    <joint name="shoulder_pan_joint" type="revolute">
        <origin rpy="0 0 0" xyz="0 0 0.1273"/>
        <axis xyz="0 0 1" />
        <limit upper="6.28318" lower="-6.28318" velocity="2.0944" effort="330" />
        <parent link="base_link" />
        <child link ="shoulder_link" />
    </joint>
    <joint name="shoulder_lift_joint" type="revolute">
        <origin rpy="0.0 1.5707963267948966 0.0" xyz="0.0 0.220941 0.0"/>
        <axis xyz="0 1 0" />
        <limit upper="6.28318" lower="-6.28318" velocity="2.0944" effort="330.0" />
        <parent link ="shoulder_link" />
        <child link="upper_arm_link" />
    </joint>
    <joint name="elbow_joint" type="revolute">
        <origin rpy="0.0 0.0 0.0" xyz="0.0 -0.1719 0.612"/>
        <axis xyz="0 1 0" />
        <limit upper="6.28318" lower="-6.28318" velocity="3.14159" effort="150.0" />
        <parent link ="upper_arm_link" />
        <child link="forearm_link" />
    </joint>
    <joint name="wrist_1_joint" type="revolute">
        <origin rpy="0.0 1.5707963267948966 0.0" xyz="0.0 0.0 0.5723"/>
        <axis xyz="0 1 0" />
        <limit upper="6.28318" lower="-6.28318" velocity="3.14159" effort="56.0" />
        <parent link ="forearm_link" />
        <child link="wrist_1_link" />
    </joint>
    <joint name="wrist_2_joint" type="revolute">
        <origin rpy="0.0 0.0 0.0" xyz="0.0 0.1149 0.0"/>
        <axis xyz="0 0 1"/>
        <limit upper="6.28318" lower="-6.28318" velocity="3.14159" effort="56.0" />
        <parent link ="wrist_1_link" />
        <child link="wrist_2_link" />
    </joint>
    <joint name="wrist_3_joint" type="revolute">
        <origin rpy="0.0 0.0 0.0" xyz="0.0 0.0 0.1157"/>
        <axis xyz="0 1 0" />
        <limit upper="6.28318" lower="-6.28318" velocity="3.14159" effort="56.0" />
        <parent link ="wrist_2_link" />
        <child link="wrist_3_link" />
    </joint>
    <joint name="ee_fixed_joint" type="fixed">
        <parent link="wrist_3_link"/>
        <child link="ee_link"/>
        <origin rpy="0.0 0.0 1.5707963267948966" xyz="0.0 0.0922 0.0"/>
    </joint>
    <link name="ee_link">
        <collision>
            <geometry>
                <box size="0.01 0.01 0.01"/>
            </geometry>
            <origin rpy="0 0 0" xyz="-0.01 0 0"/>
        </collision>
    </link>
    <joint name="hand_mount" type="fixed">
        <parent link="ee_link"/>
        <child link="palm_link"/>
        <origin rpy="0 1.5707963267948966 0" xyz="0.095 0.0 -0.01"/>
    </joint>
      <!-- PALM -->
  <link name="palm_link">
    <visual>
      <geometry>
        <mesh filename="ur10/meshes/allegro/base_link.STL"/>
      </geometry>
      <origin rpy="0 0 0" xyz="0 0 0 "/>
      <material name="black">
        <color rgba="0.2 0.2 0.2 1"/>
        <friction>
          <ode mu="0.5"/>
        </friction>
      </material>
    </visual>
    <collision>
      <origin rpy="0 0 0" xyz="-0.009300 0 -0.0475"/>
      <geometry>
        <box size="0.0408 0.1130 0.095"/>
      </geometry>
    </collision>
    <inertial>
      <origin rpy="0 0 0" xyz="0 0 0.0475"/>
      <mass value="0.4154"/>
      <inertia ixx="1e-4" ixy="0.0" ixz="0.0" iyy="1e-4" iyz="0.0" izz="1e-4"/>
    </inertial>
  </link>
  <link name="hand_ee_link">
    <origin rpy="0 0 0" xyz="0 0 0"/>
  </link>
  <joint name="hand_ee_joint" type="fixed">
    <parent link="palm_link"/>
    <child link="hand_ee_link"/>
    <origin rpy="0 0 0" xyz="0.05 0 0"/>
  </joint>
  <!-- ============================================================================= -->
  <!-- FINGERS -->
  <!-- RIGHT HAND due to which finger is number 0 -->
  <!-- for LEFT HAND switch the sign of the **offset_origin_y** and **finger_angle_r** parameters-->
  <!-- [LINK 0, 4, 8] -->
  <link name="index_link_0">
    <visual>
      <geometry>
        <mesh filename="ur10/meshes/allegro/link_0.0.STL"/>
      </geometry>
      <material name="black"/>
    </visual>
    <collision>
      <geometry>
        <box size="0.0196 0.0275 0.0164"/>
      </geometry>
      <origin rpy="0 0 0" xyz="0 0 0.0082"/>
      <surface>
        <friction>
          <ode>
            <mu>0.6</mu>
            <mu2>0.5</mu2>
          </ode>
        </friction>
      </surface>
    </collision>
    <inertial>
      <mass value="0.0119"/>
      <origin rpy="0 0 0" xyz="0 0 0"/>
      <inertia ixx="1.01666658333e-06" ixy="0.0" ixz="0.0" iyy="6.47677333333e-07" iyz="0.0" izz="1.01666658333e-06"/>
    </inertial>
  </link>
  <!-- [LINK 1, 5, 9] -->
  <link name="index_link_1">
    <visual>
      <geometry>
        <mesh filename="ur10/meshes/allegro/link_1.0.STL"/>
      </geometry>
      <material name="black">
        <friction>
          <ode mu="0.5"/>
        </friction>
      </material>
    </visual>
    <collision>
      <geometry>
        <box size="0.0196 0.0275 0.054"/>
      </geometry>
      <origin rpy="0 0 0" xyz="0 0 0.027"/>
      <surface>
        <friction>
          <ode>
            <mu>0.6</mu>
            <mu2>0.5</mu2>
          </ode>
        </friction>
      </surface>
    </collision>
    <inertial>
      <mass value="0.065"/>
      <origin rpy="0 0 0" xyz="0 0 0"/>
      <inertia ixx="7.95654166667e-05" ixy="1.7199e-05" ixz="8.75875e-06" iyy="2.47088833333e-05" iyz="2.413125e-05" izz="7.95654166667e-05"/>
    </inertial>
  </link>
  <!-- [LINK 2, 6, 10]-->
  <link name="index_link_2">
    <visual>
      <geometry>
        <mesh filename="ur10/meshes/allegro/link_2.0.STL"/>
      </geometry>
      <material name="black">
        <friction>
          <ode mu="0.5"/>
        </friction>
      </material>
    </visual>
    <collision>
      <geometry>
        <box size="0.0196 0.0275 0.0384"/>
      </geometry>
      <origin rpy="0 0 0" xyz="0 0 0.0192"/>
      <surface>
        <friction>
          <ode>
            <mu>0.6</mu>
            <mu2>0.5</mu2>
          </ode>
        </friction>
      </surface>
    </collision>
    <inertial>
      <mass value="0.0355"/>
      <origin rpy="0 0 0" xyz="0 0 0"/>
      <inertia ixx="2.63979183333e-05" ixy="6.67968e-06" ixz="4.783625e-06" iyy="1.34948516667e-05" iyz="9.372e-06" izz="2.63979183333e-05"/>
    </inertial>
  </link>
  <!-- [LINK 3, 7, 11] -->
  <link name="index_link_3">
    <visual>
      <geometry>
        <mesh filename="ur10/meshes/allegro/link_3.0.STL"/>
      </geometry>
      <material name="black">
        <friction>
          <ode mu="0.5"/>
        </friction>
      </material>
    </visual>
    <collision>
      <geometry>
        <box size="0.0196 0.0275 0.0267"/>
      </geometry>
      <origin rpy="0 0 0" xyz="0 0 0.01335"/>
      <surface>
        <friction>
          <ode>
            <mu>0.6</mu>
            <mu2>0.5</mu2>
          </ode>
        </friction>
      </surface>
    </collision>
    <inertial>
      <mass value="0.0096"/>
      <origin rpy="0 0 0" xyz="0 0 0"/>
      <inertia ixx="4.701248e-06" ixy="1.255968e-06" ixz="1.2936e-06" iyy="3.649312e-06" iyz="1.7622e-06" izz="4.701248e-06"/>
    </inertial>
  </link>
  <!-- [FINGER TIP] -->
  <link name="index_fingertip">
    <visual>
      <geometry>
        <mesh filename="ur10/meshes/allegro/link_3.0_tip.STL"/>
      </geometry>
      <material name="white">
        <color rgba=".9 .9 .9 1"/>
      </material>
    </visual>
    <collision>
      <geometry>
        <sphere radius="0.012"/>
      </geometry>
      <surface>
        <friction>
          <ode>
            <mu>0.6</mu>
            <mu2>0.5</mu2>
          </ode>
        </friction>
      </surface>
    </collision>
    <inertial>
      <mass value="0.0168"/>
      <origin rpy="0 0 0" xyz="0 0 0"/>
      <inertia ixx="9.68e-07" ixy="0" ixz="0" iyy="9.68e-07" iyz="0" izz="9.68e-07"/>
    </inertial>
  </link>
  <!-- [LINK 0, 4, 8] -->
  <link name="middle_link_0">
    <visual>
      <geometry>
        <mesh filename="ur10/meshes/allegro/link_0.0.STL"/>
      </geometry>
      <material name="black"/>
    </visual>
    <collision>
      <geometry>
        <box size="0.0196 0.0275 0.0164"/>
      </geometry>
      <origin rpy="0 0 0" xyz="0 0 0.0082"/>
      <surface>
        <friction>
          <ode>
            <mu>0.6</mu>
            <mu2>0.5</mu2>
          </ode>
        </friction>
      </surface>
    </collision>
    <inertial>
      <mass value="0.0119"/>
      <origin rpy="0 0 0" xyz="0 0 0"/>
      <inertia ixx="1.01666658333e-06" ixy="0.0" ixz="0.0" iyy="6.47677333333e-07" iyz="0.0" izz="1.01666658333e-06"/>
    </inertial>
  </link>
  <!-- [LINK 1, 5, 9] -->
  <link name="middle_link_1">
    <visual>
      <geometry>
        <mesh filename="ur10/meshes/allegro/link_1.0.STL"/>
      </geometry>
      <material name="black">
        <friction>
          <ode mu="0.5"/>
        </friction>
      </material>
    </visual>
    <collision>
      <geometry>
        <box size="0.0196 0.0275 0.054"/>
      </geometry>
      <origin rpy="0 0 0" xyz="0 0 0.027"/>
      <surface>
        <friction>
          <ode>
            <mu>0.6</mu>
            <mu2>0.5</mu2>
          </ode>
        </friction>
      </surface>
    </collision>
    <inertial>
      <mass value="0.065"/>
      <origin rpy="0 0 0" xyz="0 0 0"/>
      <inertia ixx="7.95654166667e-05" ixy="1.7199e-05" ixz="8.75875e-06" iyy="2.47088833333e-05" iyz="2.413125e-05" izz="7.95654166667e-05"/>
    </inertial>
  </link>
  <!-- [LINK 2, 6, 10]-->
  <link name="middle_link_2">
    <visual>
      <geometry>
        <mesh filename="ur10/meshes/allegro/link_2.0.STL"/>
      </geometry>
      <material name="black">
        <friction>
          <ode mu="0.5"/>
        </friction>
      </material>
    </visual>
    <collision>
      <geometry>
        <box size="0.0196 0.0275 0.0384"/>
      </geometry>
      <origin rpy="0 0 0" xyz="0 0 0.0192"/>
      <surface>
        <friction>
          <ode>
            <mu>0.6</mu>
            <mu2>0.5</mu2>
          </ode>
        </friction>
      </surface>
    </collision>
    <inertial>
      <mass value="0.0355"/>
      <origin rpy="0 0 0" xyz="0 0 0"/>
      <inertia ixx="2.63979183333e-05" ixy="6.67968e-06" ixz="4.783625e-06" iyy="1.34948516667e-05" iyz="9.372e-06" izz="2.63979183333e-05"/>
    </inertial>
  </link>
  <!-- [LINK 3, 7, 11] -->
  <link name="middle_link_3">
    <visual>
      <geometry>
        <mesh filename="ur10/meshes/allegro/link_3.0.STL"/>
      </geometry>
      <material name="black">
        <friction>
          <ode mu="0.5"/>
        </friction>
      </material>
    </visual>
    <collision>
      <geometry>
        <box size="0.0196 0.0275 0.0267"/>
      </geometry>
      <origin rpy="0 0 0" xyz="0 0 0.01335"/>
      <surface>
        <friction>
          <ode>
            <mu>0.6</mu>
            <mu2>0.5</mu2>
          </ode>
        </friction>
      </surface>
    </collision>
    <inertial>
      <mass value="0.0096"/>
      <origin rpy="0 0 0" xyz="0 0 0"/>
      <inertia ixx="4.701248e-06" ixy="1.255968e-06" ixz="1.2936e-06" iyy="3.649312e-06" iyz="1.7622e-06" izz="4.701248e-06"/>
    </inertial>
  </link>
  <!-- [FINGER TIP] -->
  <link name="middle_fingertip">
    <visual>
      <geometry>
        <mesh filename="ur10/meshes/allegro/link_3.0_tip.STL"/>
      </geometry>
      <material name="white">
        <color rgba=".9 .9 .9 1"/>
      </material>
    </visual>
    <collision>
      <geometry>
        <sphere radius="0.012"/>
      </geometry>
      <surface>
        <friction>
          <ode>
            <mu>0.6</mu>
            <mu2>0.5</mu2>
          </ode>
        </friction>
      </surface>
    </collision>
    <inertial>
      <mass value="0.0168"/>
      <origin rpy="0 0 0" xyz="0 0 0"/>
      <inertia ixx="9.68e-07" ixy="0" ixz="0" iyy="9.68e-07" iyz="0" izz="9.68e-07"/>
    </inertial>
  </link>
  <!-- [LINK 0, 4, 8] -->
  <link name="ring_link_0">
    <visual>
      <geometry>
        <mesh filename="ur10/meshes/allegro/link_0.0.STL"/>
      </geometry>
      <material name="black"/>
    </visual>
    <collision>
      <geometry>
        <box size="0.0196 0.0275 0.0164"/>
      </geometry>
      <origin rpy="0 0 0" xyz="0 0 0.0082"/>
      <surface>
        <friction>
          <ode>
            <mu>0.6</mu>
            <mu2>0.5</mu2>
          </ode>
        </friction>
      </surface>
    </collision>
    <inertial>
      <mass value="0.0119"/>
      <origin rpy="0 0 0" xyz="0 0 0"/>
      <inertia ixx="1.01666658333e-06" ixy="0.0" ixz="0.0" iyy="6.47677333333e-07" iyz="0.0" izz="1.01666658333e-06"/>
    </inertial>
  </link>
  <!-- [LINK 1, 5, 9] -->
  <link name="ring_link_1">
    <visual>
      <geometry>
        <mesh filename="ur10/meshes/allegro/link_1.0.STL"/>
      </geometry>
      <material name="black">
        <friction>
          <ode mu="0.5"/>
        </friction>
      </material>
    </visual>
    <collision>
      <geometry>
        <box size="0.0196 0.0275 0.054"/>
      </geometry>
      <origin rpy="0 0 0" xyz="0 0 0.027"/>
      <surface>
        <friction>
          <ode>
            <mu>0.6</mu>
            <mu2>0.5</mu2>
          </ode>
        </friction>
      </surface>
    </collision>
    <inertial>
      <mass value="0.065"/>
      <origin rpy="0 0 0" xyz="0 0 0"/>
      <inertia ixx="7.95654166667e-05" ixy="1.7199e-05" ixz="8.75875e-06" iyy="2.47088833333e-05" iyz="2.413125e-05" izz="7.95654166667e-05"/>
    </inertial>
  </link>
  <!-- [LINK 2, 6, 10]-->
  <link name="ring_link_2">
    <visual>
      <geometry>
        <mesh filename="ur10/meshes/allegro/link_2.0.STL"/>
      </geometry>
      <material name="black">
        <friction>
          <ode mu="0.5"/>
        </friction>
      </material>
    </visual>
    <collision>
      <geometry>
        <box size="0.0196 0.0275 0.0384"/>
      </geometry>
      <origin rpy="0 0 0" xyz="0 0 0.0192"/>
      <surface>
        <friction>
          <ode>
            <mu>0.6</mu>
            <mu2>0.5</mu2>
          </ode>
        </friction>
      </surface>
    </collision>
    <inertial>
      <mass value="0.0355"/>
      <origin rpy="0 0 0" xyz="0 0 0"/>
      <inertia ixx="2.63979183333e-05" ixy="6.67968e-06" ixz="4.783625e-06" iyy="1.34948516667e-05" iyz="9.372e-06" izz="2.63979183333e-05"/>
    </inertial>
  </link>
  <!-- [LINK 3, 7, 11] -->
  <link name="ring_link_3">
    <visual>
      <geometry>
        <mesh filename="ur10/meshes/allegro/link_3.0.STL"/>
      </geometry>
      <material name="black">
        <friction>
          <ode mu="0.5"/>
        </friction>
      </material>
    </visual>
    <collision>
      <geometry>
        <box size="0.0196 0.0275 0.0267"/>
      </geometry>
      <origin rpy="0 0 0" xyz="0 0 0.01335"/>
      <surface>
        <friction>
          <ode>
            <mu>0.6</mu>
            <mu2>0.5</mu2>
          </ode>
        </friction>
      </surface>
    </collision>
    <inertial>
      <mass value="0.0096"/>
      <origin rpy="0 0 0" xyz="0 0 0"/>
      <inertia ixx="4.701248e-06" ixy="1.255968e-06" ixz="1.2936e-06" iyy="3.649312e-06" iyz="1.7622e-06" izz="4.701248e-06"/>
    </inertial>
  </link>
  <!-- [FINGER TIP] -->
  <link name="ring_fingertip">
    <visual>
      <geometry>
        <mesh filename="ur10/meshes/allegro/link_3.0_tip.STL"/>
      </geometry>
      <material name="white">
        <color rgba=".9 .9 .9 1"/>
      </material>
    </visual>
    <collision>
      <geometry>
        <sphere radius="0.012"/>
      </geometry>
      <surface>
        <friction>
          <ode>
            <mu>0.6</mu>
            <mu2>0.5</mu2>
          </ode>
        </friction>
      </surface>
    </collision>
    <inertial>
      <mass value="0.0168"/>
      <origin rpy="0 0 0" xyz="0 0 0"/>
      <inertia ixx="9.68e-07" ixy="0" ixz="0" iyy="9.68e-07" iyz="0" izz="9.68e-07"/>
    </inertial>
  </link>
  <!-- THUMB -->
  <!-- [LINK 12] -->
  <link name="thumb_link_0">
    <visual>
      <geometry>
        <mesh filename="ur10/meshes/allegro/link_12.0_right.STL"/>
      </geometry>
      <material name="black">
        <color rgba=".2 .2 .2 1"/>
      </material>
    </visual>
    <collision>
      <geometry>
        <box size="0.0358 0.034 0.0455"/>
      </geometry>
      <origin rpy="0 0 0" xyz="-0.0179 0.009 0.0145"/>
      <surface>
        <friction>
          <ode>
            <mu>0.6</mu>
            <mu2>0.5</mu2>
          </ode>
        </friction>
      </surface>
    </collision>
    <inertial>
      <mass value="0.0176"/>
      <origin rpy="0 0 0" xyz="0 0 0"/>
      <inertia ixx="1.89273333333e-5" ixy="7.16716e-06" ixz="5.35568e-06" iyy="1.43008213333e-05" iyz="6.8068e-06" izz="1.89273333333e-05"/>
    </inertial>
  </link>
  <!-- [LINK 13] -->
  <link name="thumb_link_1">
    <visual>
      <geometry>
        <mesh filename="ur10/meshes/allegro/link_13.0.STL"/>
      </geometry>
      <material name="black">
        <color rgba=".2 .2 .2 1"/>
        <friction>
          <ode mu="0.5"/>
        </friction>
      </material>
    </visual>
    <collision>
      <geometry>
        <box size="0.0196 0.0275 0.0177"/>
      </geometry>
      <origin rpy="0 0 0" xyz="0 0 0.00885"/>
      <surface>
        <friction>
          <ode>
            <mu>0.6</mu>
            <mu2>0.5</mu2>
          </ode>
        </friction>
      </surface>
    </collision>
    <inertial>
      <mass value="0.0119"/>
      <origin rpy="0 0 0" xyz="0 0 0"/>
      <inertia ixx="4.24250866667e-06" ixy="1.032087e-06" ixz="1.603525e-06" iyy="4.52362633333e-06" iyz="1.44808125e-06" izz="4.24250866667e-06"/>
    </inertial>
  </link>
  <!-- [LINK 14] -->
  <link name="thumb_link_2">
    <visual>
      <geometry>
        <mesh filename="ur10/meshes/allegro/link_14.0.STL"/>
      </geometry>
      <material name="black">
      <friction>
          <ode mu="0.5"/>
        </friction>
       </material>
    </visual>
    <collision>
      <geometry>
        <box size="0.0196 0.0275 0.0514"/>
      </geometry>
      <origin rpy="0 0 0" xyz="0 0 0.0257"/>
      <surface>
        <friction>
          <ode>
            <mu>0.6</mu>
            <mu2>0.5</mu2>
          </ode>
        </friction>
      </surface>
    </collision>
    <inertial>
      <mass value="0.038"/>
      <origin rpy="0 0 0" xyz="0 0 0"/>
      <inertia ixx="4.30439933333e-05" ixy="9.57068e-06" ixz="5.1205e-06" iyy="1.44451933333e-05" iyz="1.342825e-05" izz="4.30439933333e-05"/>
    </inertial>
  </link>
  <!-- [LINK 15] -->
  <link name="thumb_link_3">
    <visual>
      <geometry>
        <mesh filename="ur10/meshes/allegro/link_15.0.STL"/>
      </geometry>
      <material name="black">
      <friction>
          <ode mu="0.5"/>
        </friction>
      </material>
    </visual>
    <collision>
      <geometry>
        <box size="0.0196 0.0275 0.0423"/>
      </geometry>
      <origin rpy="0 0 0" xyz="0 0 0.02115"/>
      <surface>
        <friction>
          <ode>
            <mu>0.6</mu>
            <mu2>0.5</mu2>
          </ode>
        </friction>
      </surface>
    </collision>
    <inertial>
      <mass value="0.0388"/>
      <origin rpy="0 0 0" xyz="0 0 0"/>
      <inertia ixx="3.29223173333e-05" ixy="8.042076e-06" ixz="5.2283e-06" iyy="1.47493026667e-5" iyz="1.1283525e-5" izz="3.29223173333e-05"/>
    </inertial>
  </link>
  <!-- [FINGER TIP] -->
  <link name="thumb_fingertip">
    <visual>
      <geometry>
        <mesh filename="ur10/meshes/allegro/link_15.0_tip.STL"/>
      </geometry>
      <material name="white">
        <color rgba=".9 .9 .9 1"/>
      </material>
    </visual>
    <collision>
      <geometry>
        <sphere radius="0.012"/>
      </geometry>
      <origin rpy="0 0 0" xyz="0 0 0"/>
      <surface>
        <friction>
          <ode>
            <mu>0.6</mu>
            <mu2>0.5</mu2>
          </ode>
        </friction>
      </surface>
    </collision>
    <inertial>
      <mass value="0.0168"/>
      <origin rpy="0 0 0" xyz="0 0 0"/>
      <inertia ixx="9.68e-07" ixy="0" ixz="0" iyy="9.68e-07" iyz="0" izz="9.68e-07"/>
    </inertial>
  </link>
  <joint name="index_joint_0" type="revolute">
    <axis xyz="0 0 1"/>
    <limit effort="0.7" lower="-0.47" upper="0.47" velocity="6.283"/>
    <parent link="palm_link"/>
    <child link="index_link_0"/>
    <origin rpy="-0.08726646255 0 0" xyz="0 0.0435 -0.001542"/>
    <dynamics damping="0.0414019" friction="0.0523963"/>
  </joint>
  <joint name="index_joint_1" type="revolute">
    <limit effort="0.7" lower="-0.196" upper="1.61" velocity="6.283"/>
    <axis xyz="0 1 0"/>
    <parent link="index_link_0"/>
    <child link="index_link_1"/>
    <origin xyz="0 0 0.0164"/>
    <dynamics damping="0.00587541" friction="0.0150275"/>
  </joint>
  <joint name="index_joint_2" type="revolute">
    <axis xyz="0 1 0"/>
    <limit effort="0.7" lower="-0.174" upper="1.709" velocity="6.283"/>
    <parent link="index_link_1"/>
    <child link="index_link_2"/>
    <origin xyz="0 0 0.054"/>
    <dynamics damping="0.010638" friction="0.00616359"/>
  </joint>
  <joint name="index_joint_3" type="revolute">
    <axis xyz="0 1 0"/>
    <limit effort="0.7" lower="-0.227" upper="1.618" velocity="6.283"/>
    <parent link="index_link_2"/>
    <child link="index_link_3"/>
    <origin xyz="0 0 0.0384"/>
    <dynamics damping="0.0226948" friction="0.0227036"/>
  </joint>
  <joint name="index_fingertip_joint" type="fixed">
    <parent link="index_link_3"/>
    <child link="index_fingertip"/>
    <origin rpy="0 0 0" xyz="0 0 0.0267"/>
  </joint>
  <joint name="middle_joint_0" type="revolute">
    <axis xyz="0 0 1"/>
    <limit effort="0.7" lower="-0.47" upper="0.47" velocity="6.283"/>
    <parent link="palm_link"/>
    <child link="middle_link_0"/>
    <origin rpy="0.0 0 0" xyz="0 0 0.0007"/>
    <dynamics damping="0.0414019" friction="0.0523963"/>
  </joint>
  <joint name="middle_joint_1" type="revolute">
    <limit effort="0.7" lower="-0.196" upper="1.61" velocity="6.283"/>
    <axis xyz="0 1 0"/>
    <parent link="middle_link_0"/>
    <child link="middle_link_1"/>
    <origin xyz="0 0 0.0164"/>
    <dynamics damping="0.00587541" friction="0.0150275"/>
  </joint>
  <joint name="middle_joint_2" type="revolute">
    <axis xyz="0 1 0"/>
    <limit effort="0.7" lower="-0.174" upper="1.709" velocity="6.283"/>
    <parent link="middle_link_1"/>
    <child link="middle_link_2"/>
    <origin xyz="0 0 0.054"/>
    <dynamics damping="0.010638" friction="0.00616359"/>
  </joint>
  <joint name="middle_joint_3" type="revolute">
    <axis xyz="0 1 0"/>
    <limit effort="0.7" lower="-0.227" upper="1.618" velocity="6.283"/>
    <parent link="middle_link_2"/>
    <child link="middle_link_3"/>
    <origin xyz="0 0 0.0384"/>
    <dynamics damping="0.0226948" friction="0.0227036"/>
  </joint>
  <joint name="middle_fingertip_joint" type="fixed">
    <parent link="middle_link_3"/>
    <child link="middle_fingertip"/>
    <origin rpy="0 0 0" xyz="0 0 0.0267"/>
  </joint>
  <joint name="ring_joint_0" type="revolute">
    <axis xyz="0 0 1"/>
    <limit effort="0.7" lower="-0.47" upper="0.47" velocity="6.283"/>
    <parent link="palm_link"/>
    <child link="ring_link_0"/>
    <origin rpy="0.08726646255 0 0" xyz="0 -0.0435 -0.001542"/>
    <dynamics damping="0.0414019" friction="0.0523963"/>
  </joint>
  <joint name="ring_joint_1" type="revolute">
    <limit effort="0.7" lower="-0.196" upper="1.61" velocity="6.283"/>
    <axis xyz="0 1 0"/>
    <parent link="ring_link_0"/>
    <child link="ring_link_1"/>
    <origin xyz="0 0 0.0164"/>
    <dynamics damping="0.00587541" friction="0.0150275"/>
  </joint>
  <joint name="ring_joint_2" type="revolute">
    <axis xyz="0 1 0"/>
    <limit effort="0.7" lower="-0.174" upper="1.709" velocity="6.283"/>
    <parent link="ring_link_1"/>
    <child link="ring_link_2"/>
    <origin xyz="0 0 0.054"/>
    <dynamics damping="0.010638" friction="0.00616359"/>
  </joint>
  <joint name="ring_joint_3" type="revolute">
    <axis xyz="0 1 0"/>
    <limit effort="0.7" lower="-0.227" upper="1.618" velocity="6.283"/>
    <parent link="ring_link_2"/>
    <child link="ring_link_3"/>
    <origin xyz="0 0 0.0384"/>
    <dynamics damping="0.0226948" friction="0.0227036"/>
  </joint>
  <joint name="ring_fingertip_joint" type="fixed">
    <parent link="ring_link_3"/>
    <child link="ring_fingertip"/>
    <origin rpy="0 0 0" xyz="0 0 0.0267"/>
  </joint>
  <joint name="thumb_joint_0" type="revolute">
    <axis xyz="-1 0 0"/>
    <limit effort="0.7" lower="0.263" upper="1.396" velocity="6.283"/>
    <parent link="palm_link"/>
    <child link="thumb_link_0"/>
    <origin rpy="0 -1.65806278845 -1.5707963259" xyz="-0.0182 0.019333 -0.045987"/>
    <dynamics friction="0.035"/>
  </joint>
  <joint name="thumb_joint_1" type="revolute">
    <axis xyz="0 0 1"/>
    <limit effort="0.7" lower="-0.105" upper="1.163" velocity="6.283"/>
    <parent link="thumb_link_0"/>
    <child link="thumb_link_1"/>
    <origin xyz="-0.027 0.005 0.0399"/>
    <dynamics friction="0.035"/>
  </joint>
  <joint name="thumb_joint_2" type="revolute">
    <axis xyz="0 1 0"/>
    <limit effort="0.7" lower="-0.189" upper="1.644" velocity="6.283"/>
    <parent link="thumb_link_1"/>
    <child link="thumb_link_2"/>
    <origin xyz="0 0 0.0177"/>
    <dynamics friction="0.035"/>
  </joint>
  <joint name="thumb_joint_3" type="revolute">
    <axis xyz="0 1 0"/>
    <limit effort="0.7" lower="-0.162" upper="1.719" velocity="6.283"/>
    <parent link="thumb_link_2"/>
    <child link="thumb_link_3"/>
    <origin xyz="0 0 0.0514"/>
    <dynamics friction="0.035"/>
  </joint>
  <joint name="thumb_fingertip_joint" type="fixed">
    <parent link="thumb_link_3"/>
    <child link="thumb_fingertip"/>
    <origin rpy="0 0 0" xyz="0 0 0.0423"/>
  </joint> 
</robot>
